Workbook

Sheet Darbs
A1: Lauks | B1: Apraksts
A2: Virsraksts | B2: Chi-square: lēmumu koks iPhone pirkuma prognozei
A3: Autori | B3: Sandris Borkovskis; Dmitrijs Dunajs
A4: Mērķis | B4: Izvēlēties sašķelšanu ar lielāko χ², izveidot koku un pierakstīt katras gala lapas JA–TAD likumu.
A5: Uzdevuma īss apraksts | B5: 15 klientu ieraksti. Pazīmes: dzimums, vecums, dzīvojamā platība, bērnu skaits un ienākumi. Mērķis: Nopirks Iphone (0 — nepirks; 1 — nopirks). ID izmanto tikai ierakstu atrašanai.
A6: Datu saglabāšana | B6: Lapā Dati ir visi 15 sākotnējie ieraksti sākotnējā secībā. Tukšā pirmā virsraksta vietā lietots ID; pārējie virsraksti un visas datu vērtības saglabātas.
A7: Svarīga izvēle | B7: Vienādām maksimālām χ² vērtībām izvēlamies pazīmi ar mazāk kategorijām šajā mezglā. Ja arī to skaits sakrīt, izvēlamies agrāko kolonnu. Tas ir šajā darbā pieņemts palīgnoteikums, nevis prezentācijas norāde.
A8: Kā lasīt aprēķinus | B8: Iterācijas apkopo četrus izvēles soļus. Mezgls_1…4 satur konkrētā mezgla datus, visu atlikušo pazīmju χ² un atsevišķi O, E, (O−E)²/E. Zaļās šūnas apzīmē izvēlēto pazīmi.
A9: Rezultāts | B9: 4 iekšējie mezgli, 8 gala lapas un 8 likumi. Visas 15 dotās rindas koks klasificē pareizi. Šī ir apmācības datu pārbaude.
A10: Avoti | B10: studentiem_3LD1_2026 (2).xlsx, lapa studentiem_dati; splitting_krit2_GR_29sept2025.pdf, 4. lpp. biežumu piemērs un 6. lpp. χ² formula.
A11: Faila lietošana | B11: Visos aprēķinos ir Excel formulas un saglabātas to vērtības. Ja maina datus, nepieciešams no jauna veidot arī mezglu sastāvu un koku; šī grāmata dokumentē konkrētos 15 ierakstus.

Sheet Dati
A1: ID | B1: Dzimums | C1: Vecums | D1: Dzīvojamā platība | E1: Bērni | F1: Ienākumi | G1: Nopirks Iphone
A2: 1 | B2: v | C2: 29 | D2: īrē | E2: 1 | F2: 60100 | G2: 0
A3: 2 | B3: v | C3: 35 | D3: īpašnieks | E3: 2 | F3: 87000 | G3: 0
A4: 3 | B4: s | C4: 48 | D4: īrē | E4: 3 | F4: 65000 | G4: 1
A5: 4 | B5: s | C5: 29 | D5: īrē | E5: 2 | F5: 87000 | G5: 1
A6: 5 | B6: v | C6: 40 | D6: īrē | E6: 4 | F6: 60100 | G6: 0
A7: 6 | B7: v | C7: 35 | D7: īrē | E7: 1 | F7: 80300 | G7: 0
A8: 7 | B8: s | C8: 40 | D8: īpašnieks | E8: 2 | F8: 65000 | G8: 1
A9: 8 | B9: v | C9: 40 | D9: īrē | E9: 2 | F9: 80300 | G9: 0
A10: 9 | B10: v | C10: 35 | D10: īpašnieks | E10: 1 | F10: 60100 | G10: 0
A11: 10 | B11: s | C11: 48 | D11: īrē | E11: 1 | F11: 60100 | G11: 1
A12: 11 | B12: s | C12: 25 | D12: īpašnieks | E12: 2 | F12: 60600 | G12: 0
A13: 12 | B13: v | C13: 29 | D13: īrē | E13: 4 | F13: 87000 | G13: 0
... A16: 15 | B16: s | C16: 35 | D16: īrē | E16: 1 | F16: 60600 | G16: 1
A19: v / s | B19: vīrietis / sieviete
A20: 0 / 1 | B20: nepirks / nopirks

Sheet Metode
A1: Lauks | B1: Apraksts
A2: O: novērotais biežums | B2: Katram pazīmes lielumam saskaita atsevišķi klasi 0 un klasi 1. Tā iegūst O₀ un O₁; nᵢ = O₀ + O₁.
A3: E: sagaidāmais biežums | B3: Eᵢⱼ = nᵢ × nⱼ / N. nᵢ ir attiecīgās pazīmes vērtības ierakstu skaits, nⱼ — klases skaits mezglā, N — visi mezgla ieraksti. Katram jaunam mezglam izmanto tā paša mezgla skaitļus.
A4: Sašķelšanas kritērijs | B4: χ² = Σᵢ Σⱼ (Oᵢⱼ − Eᵢⱼ)² / Eᵢⱼ. Jo lielāka vērtība, jo vairāk konkrētā biežumu tabula atšķiras no neatkarīgu pazīmes un klases sadalījuma.
A5: Izvēles secība | B5: 1) Lielākais χ². 2) Vienāda maksimuma gadījumā — mazāk atšķirīgu pazīmes vērtību mezglā, lai veidotu mazāk zarus. 3) Ja abi rādītāji sakrīt — sākotnējā kolonnu secība. 2. un 3. solis ir mūsu palīgnoteikums.
A6: Skaitliskās pazīmes | B6: Vecumu, bērnu skaitu un ienākumus šajā darbā izmanto kā atsevišķas kategorijas, tāpat kā prezentācijas piemēru. Skaitliskus sliekšņus neveido.
A7: Turpināšana | B7: Iegūtajām grupām atkārto izvēli starp ceļā vēl neizmantotajām pazīmēm. Tīru grupu (viena klase) tālāk nedala. Šeit visas gala lapas ir tīras.
A8: Ko nozīmē χ² šeit | B8: Izmantojam prezentācijas sašķelšanas rādītāju bez Yates korekcijas. Neizvēlamies nozīmības slieksni un neapgalvojam, ka tik mazs datu kopums pierāda statistisku saistību populācijā.
A9: Vienādības pārbaude | B9: Koka veidošanā vienādību pārbauda ar precīzām daļām (Python Fraction). Excel rāda tās pašas vērtības ar sešām zīmēm aiz komata; noapaļojums izvēli nenosaka.

Sheet Mezgls_1
A1: Mezgls M1 | B1: Iterācija 1
A2: Nosacījums | B2: Visi 15 ieraksti
A3: Izvēlētā pazīme | B3: Dzimums
A5: N: visi ieraksti | B5: =COUNTA($A$11:$A$25) -> 15
A6: n₀: klase 0 | B6: =COUNTIF($G$11:$G$25,0) -> 8
A7: n₁: klase 1 | B7: =COUNTIF($G$11:$G$25,1) -> 7
A9: Mezgla dati
A10: ID | B10: Dzimums | C10: Vecums | D10: Dzīvojamā platība | E10: Bērni | F10: Ienākumi | G10: Nopirks Iphone
A11: ='Dati'!A2 -> 1 | B11: ='Dati'!B2 -> v | C11: ='Dati'!C2 -> 29 | D11: ='Dati'!D2 -> īrē | E11: ='Dati'!E2 -> 1 | F11: ='Dati'!F2 -> 60100 | G11: ='Dati'!G2 -> 0
A12: ='Dati'!A3 -> 2 | B12: ='Dati'!B3 -> v | C12: ='Dati'!C3 -> 35 | D12: ='Dati'!D3 -> īpašnieks | E12: ='Dati'!E3 -> 2 | F12: ='Dati'!F3 -> 87000 | G12: ='Dati'!G3 -> 0
A13: ='Dati'!A4 -> 3 | B13: ='Dati'!B4 -> s | C13: ='Dati'!C4 -> 48 | D13: ='Dati'!D4 -> īrē | E13: ='Dati'!E4 -> 3 | F13: ='Dati'!F4 -> 65000 | G13: ='Dati'!G4 -> 1
A14: ='Dati'!A5 -> 4 | B14: ='Dati'!B5 -> s | C14: ='Dati'!C5 -> 29 | D14: ='Dati'!D5 -> īrē | E14: ='Dati'!E5 -> 2 | F14: ='Dati'!F5 -> 87000 | G14: ='Dati'!G5 -> 1
A15: ='Dati'!A6 -> 5 | B15: ='Dati'!B6 -> v | C15: ='Dati'!C6 -> 40 | D15: ='Dati'!D6 -> īrē | E15: ='Dati'!E6 -> 4 | F15: ='Dati'!F6 -> 60100 | G15: ='Dati'!G6 -> 0
A16: ='Dati'!A7 -> 6 | B16: ='Dati'!B7 -> v | C16: ='Dati'!C7 -> 35 | D16: ='Dati'!D7 -> īrē | E16: ='Dati'!E7 -> 1 | F16: ='Dati'!F7 -> 80300 | G16: ='Dati'!G7 -> 0
A17: ='Dati'!A8 -> 7 | B17: ='Dati'!B8 -> s | C17: ='Dati'!C8 -> 40 | D17: ='Dati'!D8 -> īpašnieks | E17: ='Dati'!E8 -> 2 | F17: ='Dati'!F8 -> 65000 | G17: ='Dati'!G8 -> 1
A18: ='Dati'!A9 -> 8 | B18: ='Dati'!B9 -> v | C18: ='Dati'!C9 -> 40 | D18: ='Dati'!D9 -> īrē | E18: ='Dati'!E9 -> 2 | F18: ='Dati'!F9 -> 80300 | G18: ='Dati'!G9 -> 0
A19: ='Dati'!A10 -> 9 | B19: ='Dati'!B10 -> v | C19: ='Dati'!C10 -> 35 | D19: ='Dati'!D10 -> īpašnieks | E19: ='Dati'!E10 -> 1 | F19: ='Dati'!F10 -> 60100 | G19: ='Dati'!G10 -> 0
A20: ='Dati'!A11 -> 10 | B20: ='Dati'!B11 -> s | C20: ='Dati'!C11 -> 48 | D20: ='Dati'!D11 -> īrē | E20: ='Dati'!E11 -> 1 | F20: ='Dati'!F11 -> 60100 | G20: ='Dati'!G11 -> 1
A21: ='Dati'!A12 -> 11 | B21: ='Dati'!B12 -> s | C21: ='Dati'!C12 -> 25 | D21: ='Dati'!D12 -> īpašnieks | E21: ='Dati'!E12 -> 2 | F21: ='Dati'!F12 -> 60600 | G21: ='Dati'!G12 -> 0
A22: ='Dati'!A13 -> 12 | B22: ='Dati'!B13 -> v | C22: ='Dati'!C13 -> 29 | D22: ='Dati'!D13 -> īrē | E22: ='Dati'!E13 -> 4 | F22: ='Dati'!F13 -> 87000 | G22: ='Dati'!G13 -> 0
... A25: ='Dati'!A16 -> 15 | B25: ='Dati'!B16 -> s | C25: ='Dati'!C16 -> 35 | D25: ='Dati'!D16 -> īrē | E25: ='Dati'!E16 -> 1 | F25: ='Dati'!F16 -> 60600 | G25: ='Dati'!G16 -> 1
A28: Pazīme | B28: χ² | C28: Kategoriju skaits | D28: Izvēle
A29: Dzimums | B29: =I40 -> 8.0404974 | C29: 2 | D29: Jā
A30: Vecums | B30: =I50 -> 4.4866071 | C30: 5 | D30: —
A31: Dzīvojamā platība | B31: =I57 -> 0.044642857 | C31: 2 | D31: —
A32: Bērni | B32: =I67 -> 2.6785714 | C32: 5 | D32: —
A33: Ienākumi | B33: =I77 -> 5.2901786 | C33: 5 | D33: —
A36: Dzimums | B36: Izvēlēts
A37: Vērtība | B37: O₀ | C37: O₁ | D37: nᵢ | E37: E₀ | F37: E₁ | G37: (O₀−E₀)²/E₀ | H37: (O₁−E₁)²/E₁ | I37: Rindas χ²
A38: s | B38: =COUNTIFS($B$11:$B$25,$A38,$G$11:$G$25,0) -> 1 | C38: =COUNTIFS($B$11:$B$25,$A38,$G$11:$G$25,1) -> 6 | D38: =SUM(B38:C38) -> 7 | E38: =D38*$B$6/$B$5 -> 3.7333333 | F38: =D38*$B$7/$B$5 -> 3.2666667 | G38: =(B38-E38)^2/E38 -> 2.0011905 | H38: =(C38-F38)^2/F38 -> 2.2870748 | I38: =SUM(G38:H38) -> 4.2882653
A39: v | B39: =COUNTIFS($B$11:$B$25,$A39,$G$11:$G$25,0) -> 7 | C39: =COUNTIFS($B$11:$B$25,$A39,$G$11:$G$25,1) -> 1 | D39: =SUM(B39:C39) -> 8 | E39: =D39*$B$6/$B$5 -> 4.2666667 | F39: =D39*$B$7/$B$5 -> 3.7333333 | G39: =(B39-E39)^2/E39 -> 1.7510417 | H39: =(C39-F39)^2/F39 -> 2.0011905 | I39: =SUM(G39:H39) -> 3.7522321
A40: χ² kopā | I40: =SUM(I38:I39) -> 8.0404974
A43: Vecums | B43: Salīdzināts
A44: Vērtība | B44: O₀ | C44: O₁ | D44: nᵢ | E44: E₀ | F44: E₁ | G44: (O₀−E₀)²/E₀ | H44: (O₁−E₁)²/E₁ | I44: Rindas χ²
A45: 25 | B45: =COUNTIFS($C$11:$C$25,$A45,$G$11:$G$25,0) -> 1 | C45: =COUNTIFS($C$11:$C$25,$A45,$G$11:$G$25,1) -> 0 | D45: =SUM(B45:C45) -> 1 | E45: =D45*$B$6/$B$5 -> 0.53333333 | F45: =D45*$B$7/$B$5 -> 0.46666667 | G45: =(B45-E45)^2/E45 -> 0.40833333 | H45: =(C45-F45)^2/F45 -> 0.46666667 | I45: =SUM(G45:H45) -> 0.875
A46: 29 | B46: =COUNTIFS($C$11:$C$25,$A46,$G$11:$G$25,0) -> 2 | C46: =COUNTIFS($C$11:$C$25,$A46,$G$11:$G$25,1) -> 1 | D46: =SUM(B46:C46) -> 3 | E46: =D46*$B$6/$B$5 -> 1.6 | F46: =D46*$B$7/$B$5 -> 1.4 | G46: =(B46-E46)^2/E46 -> 0.1 | H46: =(C46-F46)^2/F46 -> 0.11428571 | I46: =SUM(G46:H46) -> 0.21428571
A47: 35 | B47: =COUNTIFS($C$11:$C$25,$A47,$G$11:$G$25,0) -> 3 | C47: =COUNTIFS($C$11:$C$25,$A47,$G$11:$G$25,1) -> 1 | D47: =SUM(B47:C47) -> 4 | E47: =D47*$B$6/$B$5 -> 2.1333333 | F47: =D47*$B$7/$B$5 -> 1.8666667 | G47: =(B47-E47)^2/E47 -> 0.35208333 | H47: =(C47-F47)^2/F47 -> 0.40238095 | I47: =SUM(G47:H47) -> 0.75446429
A48: 40 | B48: =COUNTIFS($C$11:$C$25,$A48,$G$11:$G$25,0) -> 2 | C48: =COUNTIFS($C$11:$C$25,$A48,$G$11:$G$25,1) -> 3 | D48: =SUM(B48:C48) -> 5 | E48: =D48*$B$6/$B$5 -> 2.6666667 | F48: =D48*$B$7/$B$5 -> 2.3333333 | G48: =(B48-E48)^2/E48 -> 0.16666667 | H48: =(C48-F48)^2/F48 -> 0.19047619 | I48: =SUM(G48:H48) -> 0.35714286
A49: 48 | B49: =COUNTIFS($C$11:$C$25,$A49,$G$11:$G$25,0) -> 0 | C49: =COUNTIFS($C$11:$C$25,$A49,$G$11:$G$25,1) -> 2 | D49: =SUM(B49:C49) -> 2 | E49: =D49*$B$6/$B$5 -> 1.0666667 | F49: =D49*$B$7/$B$5 -> 0.93333333 | G49: =(B49-E49)^2/E49 -> 1.0666667 | H49: =(C49-F49)^2/F49 -> 1.2190476 | I49: =SUM(G49:H49) -> 2.2857143
A50: χ² kopā | I50: =SUM(I45:I49) -> 4.4866071
...

Sheet Mezgls_2
A1: Mezgls M2 | B1: Iterācija 2
A2: Nosacījums | B2: Dzimums = s
A3: Izvēlētā pazīme | B3: Vecums
A5: N: visi ieraksti | B5: =COUNTA($A$11:$A$17) -> 7
A6: n₀: klase 0 | B6: =COUNTIF($G$11:$G$17,0) -> 1
A7: n₁: klase 1 | B7: =COUNTIF($G$11:$G$17,1) -> 6
A9: Mezgla dati
A10: ID | B10: Dzimums | C10: Vecums | D10: Dzīvojamā platība | E10: Bērni | F10: Ienākumi | G10: Nopirks Iphone
A11: ='Dati'!A4 -> 3 | B11: ='Dati'!B4 -> s | C11: ='Dati'!C4 -> 48 | D11: ='Dati'!D4 -> īrē | E11: ='Dati'!E4 -> 3 | F11: ='Dati'!F4 -> 65000 | G11: ='Dati'!G4 -> 1
A12: ='Dati'!A5 -> 4 | B12: ='Dati'!B5 -> s | C12: ='Dati'!C5 -> 29 | D12: ='Dati'!D5 -> īrē | E12: ='Dati'!E5 -> 2 | F12: ='Dati'!F5 -> 87000 | G12: ='Dati'!G5 -> 1
A13: ='Dati'!A8 -> 7 | B13: ='Dati'!B8 -> s | C13: ='Dati'!C8 -> 40 | D13: ='Dati'!D8 -> īpašnieks | E13: ='Dati'!E8 -> 2 | F13: ='Dati'!F8 -> 65000 | G13: ='Dati'!G8 -> 1
A14: ='Dati'!A11 -> 10 | B14: ='Dati'!B11 -> s | C14: ='Dati'!C11 -> 48 | D14: ='Dati'!D11 -> īrē | E14: ='Dati'!E11 -> 1 | F14: ='Dati'!F11 -> 60100 | G14: ='Dati'!G11 -> 1
A15: ='Dati'!A12 -> 11 | B15: ='Dati'!B12 -> s | C15: ='Dati'!C12 -> 25 | D15: ='Dati'!D12 -> īpašnieks | E15: ='Dati'!E12 -> 2 | F15: ='Dati'!F12 -> 60600 | G15: ='Dati'!G12 -> 0
A16: ='Dati'!A15 -> 14 | B16: ='Dati'!B15 -> s | C16: ='Dati'!C15 -> 40 | D16: ='Dati'!D15 -> īpašnieks | E16: ='Dati'!E15 -> 0 | F16: ='Dati'!F15 -> 60600 | G16: ='Dati'!G15 -> 1
A17: ='Dati'!A16 -> 15 | B17: ='Dati'!B16 -> s | C17: ='Dati'!C16 -> 35 | D17: ='Dati'!D16 -> īrē | E17: ='Dati'!E16 -> 1 | F17: ='Dati'!F16 -> 60600 | G17: ='Dati'!G16 -> 1
A20: Pazīme | B20: χ² | C20: Kategoriju skaits | D20: Izvēle
A21: Vecums | B21: =I34 -> 7 | C21: 5 | D21: Jā
A22: Dzīvojamā platība | B22: =I41 -> 1.5555556 | C22: 2 | D22: —
A23: Bērni | B23: =I50 -> 1.5555556 | C23: 4 | D23: —
A24: Ienākumi | B24: =I59 -> 1.5555556 | C24: 4 | D24: —
A27: Vecums | B27: Izvēlēts
A28: Vērtība | B28: O₀ | C28: O₁ | D28: nᵢ | E28: E₀ | F28: E₁ | G28: (O₀−E₀)²/E₀ | H28: (O₁−E₁)²/E₁ | I28: Rindas χ²
A29: 25 | B29: =COUNTIFS($C$11:$C$17,$A29,$G$11:$G$17,0) -> 1 | C29: =COUNTIFS($C$11:$C$17,$A29,$G$11:$G$17,1) -> 0 | D29: =SUM(B29:C29) -> 1 | E29: =D29*$B$6/$B$5 -> 0.14285714 | F29: =D29*$B$7/$B$5 -> 0.85714286 | G29: =(B29-E29)^2/E29 -> 5.1428571 | H29: =(C29-F29)^2/F29 -> 0.85714286 | I29: =SUM(G29:H29) -> 6
A30: 29 | B30: =COUNTIFS($C$11:$C$17,$A30,$G$11:$G$17,0) -> 0 | C30: =COUNTIFS($C$11:$C$17,$A30,$G$11:$G$17,1) -> 1 | D30: =SUM(B30:C30) -> 1 | E30: =D30*$B$6/$B$5 -> 0.14285714 | F30: =D30*$B$7/$B$5 -> 0.85714286 | G30: =(B30-E30)^2/E30 -> 0.14285714 | H30: =(C30-F30)^2/F30 -> 0.023809524 | I30: =SUM(G30:H30) -> 0.16666667
A31: 35 | B31: =COUNTIFS($C$11:$C$17,$A31,$G$11:$G$17,0) -> 0 | C31: =COUNTIFS($C$11:$C$17,$A31,$G$11:$G$17,1) -> 1 | D31: =SUM(B31:C31) -> 1 | E31: =D31*$B$6/$B$5 -> 0.14285714 | F31: =D31*$B$7/$B$5 -> 0.85714286 | G31: =(B31-E31)^2/E31 -> 0.14285714 | H31: =(C31-F31)^2/F31 -> 0.023809524 | I31: =SUM(G31:H31) -> 0.16666667
A32: 40 | B32: =COUNTIFS($C$11:$C$17,$A32,$G$11:$G$17,0) -> 0 | C32: =COUNTIFS($C$11:$C$17,$A32,$G$11:$G$17,1) -> 2 | D32: =SUM(B32:C32) -> 2 | E32: =D32*$B$6/$B$5 -> 0.28571429 | F32: =D32*$B$7/$B$5 -> 1.7142857 | G32: =(B32-E32)^2/E32 -> 0.28571429 | H32: =(C32-F32)^2/F32 -> 0.047619048 | I32: =SUM(G32:H32) -> 0.33333333
A33: 48 | B33: =COUNTIFS($C$11:$C$17,$A33,$G$11:$G$17,0) -> 0 | C33: =COUNTIFS($C$11:$C$17,$A33,$G$11:$G$17,1) -> 2 | D33: =SUM(B33:C33) -> 2 | E33: =D33*$B$6/$B$5 -> 0.28571429 | F33: =D33*$B$7/$B$5 -> 1.7142857 | G33: =(B33-E33)^2/E33 -> 0.28571429 | H33: =(C33-F33)^2/F33 -> 0.047619048 | I33: =SUM(G33:H33) -> 0.33333333
A34: χ² kopā | I34: =SUM(I29:I33) -> 7
A37: Dzīvojamā platība | B37: Salīdzināts
A38: Vērtība | B38: O₀ | C38: O₁ | D38: nᵢ | E38: E₀ | F38: E₁ | G38: (O₀−E₀)²/E₀ | H38: (O₁−E₁)²/E₁ | I38: Rindas χ²
A39: īpašnieks | B39: =COUNTIFS($D$11:$D$17,$A39,$G$11:$G$17,0) -> 1 | C39: =COUNTIFS($D$11:$D$17,$A39,$G$11:$G$17,1) -> 2 | D39: =SUM(B39:C39) -> 3 | E39: =D39*$B$6/$B$5 -> 0.42857143 | F39: =D39*$B$7/$B$5 -> 2.5714286 | G39: =(B39-E39)^2/E39 -> 0.76190476 | H39: =(C39-F39)^2/F39 -> 0.12698413 | I39: =SUM(G39:H39) -> 0.88888889
A40: īrē | B40: =COUNTIFS($D$11:$D$17,$A40,$G$11:$G$17,0) -> 0 | C40: =COUNTIFS($D$11:$D$17,$A40,$G$11:$G$17,1) -> 4 | D40: =SUM(B40:C40) -> 4 | E40: =D40*$B$6/$B$5 -> 0.57142857 | F40: =D40*$B$7/$B$5 -> 3.4285714 | G40: =(B40-E40)^2/E40 -> 0.57142857 | H40: =(C40-F40)^2/F40 -> 0.095238095 | I40: =SUM(G40:H40) -> 0.66666667
A41: χ² kopā | I41: =SUM(I39:I40) -> 1.5555556
A44: Bērni | B44: Salīdzināts
A45: Vērtība | B45: O₀ | C45: O₁ | D45: nᵢ | E45: E₀ | F45: E₁ | G45: (O₀−E₀)²/E₀ | H45: (O₁−E₁)²/E₁ | I45: Rindas χ²
A46: 0 | B46: =COUNTIFS($E$11:$E$17,$A46,$G$11:$G$17,0) -> 0 | C46: =COUNTIFS($E$11:$E$17,$A46,$G$11:$G$17,1) -> 1 | D46: =SUM(B46:C46) -> 1 | E46: =D46*$B$6/$B$5 -> 0.14285714 | F46: =D46*$B$7/$B$5 -> 0.85714286 | G46: =(B46-E46)^2/E46 -> 0.14285714 | H46: =(C46-F46)^2/F46 -> 0.023809524 | I46: =SUM(G46:H46) -> 0.16666667
A47: 1 | B47: =COUNTIFS($E$11:$E$17,$A47,$G$11:$G$17,0) -> 0 | C47: =COUNTIFS($E$11:$E$17,$A47,$G$11:$G$17,1) -> 2 | D47: =SUM(B47:C47) -> 2 | E47: =D47*$B$6/$B$5 -> 0.28571429 | F47: =D47*$B$7/$B$5 -> 1.7142857 | G47: =(B47-E47)^2/E47 -> 0.28571429 | H47: =(C47-F47)^2/F47 -> 0.047619048 | I47: =SUM(G47:H47) -> 0.33333333
A48: 2 | B48: =COUNTIFS($E$11:$E$17,$A48,$G$11:$G$17,0) -> 1 | C48: =COUNTIFS($E$11:$E$17,$A48,$G$11:$G$17,1) -> 2 | D48: =SUM(B48:C48) -> 3 | E48: =D48*$B$6/$B$5 -> 0.42857143 | F48: =D48*$B$7/$B$5 -> 2.5714286 | G48: =(B48-E48)^2/E48 -> 0.76190476 | H48: =(C48-F48)^2/F48 -> 0.12698413 | I48: =SUM(G48:H48) -> 0.88888889
A49: 3 | B49: =COUNTIFS($E$11:$E$17,$A49,$G$11:$G$17,0) -> 0 | C49: =COUNTIFS($E$11:$E$17,$A49,$G$11:$G$17,1) -> 1 | D49: =SUM(B49:C49) -> 1 | E49: =D49*$B$6/$B$5 -> 0.14285714 | F49: =D49*$B$7/$B$5 -> 0.85714286 | G49: =(B49-E49)^2/E49 -> 0.14285714 | H49: =(C49-F49)^2/F49 -> 0.023809524 | I49: =SUM(G49:H49) -> 0.16666667
A50: χ² kopā | I50: =SUM(I46:I49) -> 1.5555556
...

Sheet Mezgls_3
A1: Mezgls M3 | B1: Iterācija 3
A2: Nosacījums | B2: Dzimums = v
A3: Izvēlētā pazīme | B3: Dzīvojamā platība
A5: N: visi ieraksti | B5: =COUNTA($A$11:$A$18) -> 8
A6: n₀: klase 0 | B6: =COUNTIF($G$11:$G$18,0) -> 7
A7: n₁: klase 1 | B7: =COUNTIF($G$11:$G$18,1) -> 1
A9: Mezgla dati
A10: ID | B10: Dzimums | C10: Vecums | D10: Dzīvojamā platība | E10: Bērni | F10: Ienākumi | G10: Nopirks Iphone
A11: ='Dati'!A2 -> 1 | B11: ='Dati'!B2 -> v | C11: ='Dati'!C2 -> 29 | D11: ='Dati'!D2 -> īrē | E11: ='Dati'!E2 -> 1 | F11: ='Dati'!F2 -> 60100 | G11: ='Dati'!G2 -> 0
A12: ='Dati'!A3 -> 2 | B12: ='Dati'!B3 -> v | C12: ='Dati'!C3 -> 35 | D12: ='Dati'!D3 -> īpašnieks | E12: ='Dati'!E3 -> 2 | F12: ='Dati'!F3 -> 87000 | G12: ='Dati'!G3 -> 0
A13: ='Dati'!A6 -> 5 | B13: ='Dati'!B6 -> v | C13: ='Dati'!C6 -> 40 | D13: ='Dati'!D6 -> īrē | E13: ='Dati'!E6 -> 4 | F13: ='Dati'!F6 -> 60100 | G13: ='Dati'!G6 -> 0
A14: ='Dati'!A7 -> 6 | B14: ='Dati'!B7 -> v | C14: ='Dati'!C7 -> 35 | D14: ='Dati'!D7 -> īrē | E14: ='Dati'!E7 -> 1 | F14: ='Dati'!F7 -> 80300 | G14: ='Dati'!G7 -> 0
A15: ='Dati'!A9 -> 8 | B15: ='Dati'!B9 -> v | C15: ='Dati'!C9 -> 40 | D15: ='Dati'!D9 -> īrē | E15: ='Dati'!E9 -> 2 | F15: ='Dati'!F9 -> 80300 | G15: ='Dati'!G9 -> 0
A16: ='Dati'!A10 -> 9 | B16: ='Dati'!B10 -> v | C16: ='Dati'!C10 -> 35 | D16: ='Dati'!D10 -> īpašnieks | E16: ='Dati'!E10 -> 1 | F16: ='Dati'!F10 -> 60100 | G16: ='Dati'!G10 -> 0
A17: ='Dati'!A13 -> 12 | B17: ='Dati'!B13 -> v | C17: ='Dati'!C13 -> 29 | D17: ='Dati'!D13 -> īrē | E17: ='Dati'!E13 -> 4 | F17: ='Dati'!F13 -> 87000 | G17: ='Dati'!G13 -> 0
A18: ='Dati'!A14 -> 13 | B18: ='Dati'!B14 -> v | C18: ='Dati'!C14 -> 40 | D18: ='Dati'!D14 -> īpašnieks | E18: ='Dati'!E14 -> 4 | F18: ='Dati'!F14 -> 87000 | G18: ='Dati'!G14 -> 1
A21: Pazīme | B21: χ² | C21: Kategoriju skaits | D21: Izvēle
A22: Vecums | B22: =I33 -> 1.9047619 | C22: 3 | D22: —
A23: Dzīvojamā platība | B23: =I40 -> 1.9047619 | C23: 2 | D23: Jā
A24: Bērni | B24: =I48 -> 1.9047619 | C24: 3 | D24: —
A25: Ienākumi | B25: =I56 -> 1.9047619 | C25: 3 | D25: —
A28: Vecums | B28: Salīdzināts
A29: Vērtība | B29: O₀ | C29: O₁ | D29: nᵢ | E29: E₀ | F29: E₁ | G29: (O₀−E₀)²/E₀ | H29: (O₁−E₁)²/E₁ | I29: Rindas χ²
A30: 29 | B30: =COUNTIFS($C$11:$C$18,$A30,$G$11:$G$18,0) -> 2 | C30: =COUNTIFS($C$11:$C$18,$A30,$G$11:$G$18,1) -> 0 | D30: =SUM(B30:C30) -> 2 | E30: =D30*$B$6/$B$5 -> 1.75 | F30: =D30*$B$7/$B$5 -> 0.25 | G30: =(B30-E30)^2/E30 -> 0.035714286 | H30: =(C30-F30)^2/F30 -> 0.25 | I30: =SUM(G30:H30) -> 0.28571429
A31: 35 | B31: =COUNTIFS($C$11:$C$18,$A31,$G$11:$G$18,0) -> 3 | C31: =COUNTIFS($C$11:$C$18,$A31,$G$11:$G$18,1) -> 0 | D31: =SUM(B31:C31) -> 3 | E31: =D31*$B$6/$B$5 -> 2.625 | F31: =D31*$B$7/$B$5 -> 0.375 | G31: =(B31-E31)^2/E31 -> 0.053571429 | H31: =(C31-F31)^2/F31 -> 0.375 | I31: =SUM(G31:H31) -> 0.42857143
A32: 40 | B32: =COUNTIFS($C$11:$C$18,$A32,$G$11:$G$18,0) -> 2 | C32: =COUNTIFS($C$11:$C$18,$A32,$G$11:$G$18,1) -> 1 | D32: =SUM(B32:C32) -> 3 | E32: =D32*$B$6/$B$5 -> 2.625 | F32: =D32*$B$7/$B$5 -> 0.375 | G32: =(B32-E32)^2/E32 -> 0.14880952 | H32: =(C32-F32)^2/F32 -> 1.0416667 | I32: =SUM(G32:H32) -> 1.1904762
A33: χ² kopā | I33: =SUM(I30:I32) -> 1.9047619
A36: Dzīvojamā platība | B36: Izvēlēts
A37: Vērtība | B37: O₀ | C37: O₁ | D37: nᵢ | E37: E₀ | F37: E₁ | G37: (O₀−E₀)²/E₀ | H37: (O₁−E₁)²/E₁ | I37: Rindas χ²
A38: īpašnieks | B38: =COUNTIFS($D$11:$D$18,$A38,$G$11:$G$18,0) -> 2 | C38: =COUNTIFS($D$11:$D$18,$A38,$G$11:$G$18,1) -> 1 | D38: =SUM(B38:C38) -> 3 | E38: =D38*$B$6/$B$5 -> 2.625 | F38: =D38*$B$7/$B$5 -> 0.375 | G38: =(B38-E38)^2/E38 -> 0.14880952 | H38: =(C38-F38)^2/F38 -> 1.0416667 | I38: =SUM(G38:H38) -> 1.1904762
A39: īrē | B39: =COUNTIFS($D$11:$D$18,$A39,$G$11:$G$18,0) -> 5 | C39: =COUNTIFS($D$11:$D$18,$A39,$G$11:$G$18,1) -> 0 | D39: =SUM(B39:C39) -> 5 | E39: =D39*$B$6/$B$5 -> 4.375 | F39: =D39*$B$7/$B$5 -> 0.625 | G39: =(B39-E39)^2/E39 -> 0.089285714 | H39: =(C39-F39)^2/F39 -> 0.625 | I39: =SUM(G39:H39) -> 0.71428571
A40: χ² kopā | I40: =SUM(I38:I39) -> 1.9047619
A43: Bērni | B43: Salīdzināts
A44: Vērtība | B44: O₀ | C44: O₁ | D44: nᵢ | E44: E₀ | F44: E₁ | G44: (O₀−E₀)²/E₀ | H44: (O₁−E₁)²/E₁ | I44: Rindas χ²
A45: 1 | B45: =COUNTIFS($E$11:$E$18,$A45,$G$11:$G$18,0) -> 3 | C45: =COUNTIFS($E$11:$E$18,$A45,$G$11:$G$18,1) -> 0 | D45: =SUM(B45:C45) -> 3 | E45: =D45*$B$6/$B$5 -> 2.625 | F45: =D45*$B$7/$B$5 -> 0.375 | G45: =(B45-E45)^2/E45 -> 0.053571429 | H45: =(C45-F45)^2/F45 -> 0.375 | I45: =SUM(G45:H45) -> 0.42857143
A46: 2 | B46: =COUNTIFS($E$11:$E$18,$A46,$G$11:$G$18,0) -> 2 | C46: =COUNTIFS($E$11:$E$18,$A46,$G$11:$G$18,1) -> 0 | D46: =SUM(B46:C46) -> 2 | E46: =D46*$B$6/$B$5 -> 1.75 | F46: =D46*$B$7/$B$5 -> 0.25 | G46: =(B46-E46)^2/E46 -> 0.035714286 | H46: =(C46-F46)^2/F46 -> 0.25 | I46: =SUM(G46:H46) -> 0.28571429
A47: 4 | B47: =COUNTIFS($E$11:$E$18,$A47,$G$11:$G$18,0) -> 2 | C47: =COUNTIFS($E$11:$E$18,$A47,$G$11:$G$18,1) -> 1 | D47: =SUM(B47:C47) -> 3 | E47: =D47*$B$6/$B$5 -> 2.625 | F47: =D47*$B$7/$B$5 -> 0.375 | G47: =(B47-E47)^2/E47 -> 0.14880952 | H47: =(C47-F47)^2/F47 -> 1.0416667 | I47: =SUM(G47:H47) -> 1.1904762
A48: χ² kopā | I48: =SUM(I45:I47) -> 1.9047619
A51: Ienākumi | B51: Salīdzināts
A52: Vērtība | B52: O₀ | C52: O₁ | D52: nᵢ | E52: E₀ | F52: E₁ | G52: (O₀−E₀)²/E₀ | H52: (O₁−E₁)²/E₁ | I52: Rindas χ²
...

Sheet Mezgls_4
A1: Mezgls M4 | B1: Iterācija 4
A2: Nosacījums | B2: Dzimums = v UN Dzīvojamā platība = īpašnieks
A3: Izvēlētā pazīme | B3: Vecums
A5: N: visi ieraksti | B5: =COUNTA($A$11:$A$13) -> 3
A6: n₀: klase 0 | B6: =COUNTIF($G$11:$G$13,0) -> 2
A7: n₁: klase 1 | B7: =COUNTIF($G$11:$G$13,1) -> 1
A9: Mezgla dati
A10: ID | B10: Dzimums | C10: Vecums | D10: Dzīvojamā platība | E10: Bērni | F10: Ienākumi | G10: Nopirks Iphone
A11: ='Dati'!A3 -> 2 | B11: ='Dati'!B3 -> v | C11: ='Dati'!C3 -> 35 | D11: ='Dati'!D3 -> īpašnieks | E11: ='Dati'!E3 -> 2 | F11: ='Dati'!F3 -> 87000 | G11: ='Dati'!G3 -> 0
A12: ='Dati'!A10 -> 9 | B12: ='Dati'!B10 -> v | C12: ='Dati'!C10 -> 35 | D12: ='Dati'!D10 -> īpašnieks | E12: ='Dati'!E10 -> 1 | F12: ='Dati'!F10 -> 60100 | G12: ='Dati'!G10 -> 0
A13: ='Dati'!A14 -> 13 | B13: ='Dati'!B14 -> v | C13: ='Dati'!C14 -> 40 | D13: ='Dati'!D14 -> īpašnieks | E13: ='Dati'!E14 -> 4 | F13: ='Dati'!F14 -> 87000 | G13: ='Dati'!G14 -> 1
A16: Pazīme | B16: χ² | C16: Kategoriju skaits | D16: Izvēle
A17: Vecums | B17: =I26 -> 3 | C17: 2 | D17: Jā
A18: Bērni | B18: =I34 -> 3 | C18: 3 | D18: —
A19: Ienākumi | B19: =I41 -> 0.75 | C19: 2 | D19: —
A22: Vecums | B22: Izvēlēts
A23: Vērtība | B23: O₀ | C23: O₁ | D23: nᵢ | E23: E₀ | F23: E₁ | G23: (O₀−E₀)²/E₀ | H23: (O₁−E₁)²/E₁ | I23: Rindas χ²
A24: 35 | B24: =COUNTIFS($C$11:$C$13,$A24,$G$11:$G$13,0) -> 2 | C24: =COUNTIFS($C$11:$C$13,$A24,$G$11:$G$13,1) -> 0 | D24: =SUM(B24:C24) -> 2 | E24: =D24*$B$6/$B$5 -> 1.3333333 | F24: =D24*$B$7/$B$5 -> 0.66666667 | G24: =(B24-E24)^2/E24 -> 0.33333333 | H24: =(C24-F24)^2/F24 -> 0.66666667 | I24: =SUM(G24:H24) -> 1
A25: 40 | B25: =COUNTIFS($C$11:$C$13,$A25,$G$11:$G$13,0) -> 0 | C25: =COUNTIFS($C$11:$C$13,$A25,$G$11:$G$13,1) -> 1 | D25: =SUM(B25:C25) -> 1 | E25: =D25*$B$6/$B$5 -> 0.66666667 | F25: =D25*$B$7/$B$5 -> 0.33333333 | G25: =(B25-E25)^2/E25 -> 0.66666667 | H25: =(C25-F25)^2/F25 -> 1.3333333 | I25: =SUM(G25:H25) -> 2
A26: χ² kopā | I26: =SUM(I24:I25) -> 3
A29: Bērni | B29: Salīdzināts
A30: Vērtība | B30: O₀ | C30: O₁ | D30: nᵢ | E30: E₀ | F30: E₁ | G30: (O₀−E₀)²/E₀ | H30: (O₁−E₁)²/E₁ | I30: Rindas χ²
A31: 1 | B31: =COUNTIFS($E$11:$E$13,$A31,$G$11:$G$13,0) -> 1 | C31: =COUNTIFS($E$11:$E$13,$A31,$G$11:$G$13,1) -> 0 | D31: =SUM(B31:C31) -> 1 | E31: =D31*$B$6/$B$5 -> 0.66666667 | F31: =D31*$B$7/$B$5 -> 0.33333333 | G31: =(B31-E31)^2/E31 -> 0.16666667 | H31: =(C31-F31)^2/F31 -> 0.33333333 | I31: =SUM(G31:H31) -> 0.5
A32: 2 | B32: =COUNTIFS($E$11:$E$13,$A32,$G$11:$G$13,0) -> 1 | C32: =COUNTIFS($E$11:$E$13,$A32,$G$11:$G$13,1) -> 0 | D32: =SUM(B32:C32) -> 1 | E32: =D32*$B$6/$B$5 -> 0.66666667 | F32: =D32*$B$7/$B$5 -> 0.33333333 | G32: =(B32-E32)^2/E32 -> 0.16666667 | H32: =(C32-F32)^2/F32 -> 0.33333333 | I32: =SUM(G32:H32) -> 0.5
A33: 4 | B33: =COUNTIFS($E$11:$E$13,$A33,$G$11:$G$13,0) -> 0 | C33: =COUNTIFS($E$11:$E$13,$A33,$G$11:$G$13,1) -> 1 | D33: =SUM(B33:C33) -> 1 | E33: =D33*$B$6/$B$5 -> 0.66666667 | F33: =D33*$B$7/$B$5 -> 0.33333333 | G33: =(B33-E33)^2/E33 -> 0.66666667 | H33: =(C33-F33)^2/F33 -> 1.3333333 | I33: =SUM(G33:H33) -> 2
A34: χ² kopā | I34: =SUM(I31:I33) -> 3
A37: Ienākumi | B37: Salīdzināts
A38: Vērtība | B38: O₀ | C38: O₁ | D38: nᵢ | E38: E₀ | F38: E₁ | G38: (O₀−E₀)²/E₀ | H38: (O₁−E₁)²/E₁ | I38: Rindas χ²
A39: 60100 | B39: =COUNTIFS($F$11:$F$13,$A39,$G$11:$G$13,0) -> 1 | C39: =COUNTIFS($F$11:$F$13,$A39,$G$11:$G$13,1) -> 0 | D39: =SUM(B39:C39) -> 1 | E39: =D39*$B$6/$B$5 -> 0.66666667 | F39: =D39*$B$7/$B$5 -> 0.33333333 | G39: =(B39-E39)^2/E39 -> 0.16666667 | H39: =(C39-F39)^2/F39 -> 0.33333333 | I39: =SUM(G39:H39) -> 0.5
A40: 87000 | B40: =COUNTIFS($F$11:$F$13,$A40,$G$11:$G$13,0) -> 1 | C40: =COUNTIFS($F$11:$F$13,$A40,$G$11:$G$13,1) -> 1 | D40: =SUM(B40:C40) -> 2 | E40: =D40*$B$6/$B$5 -> 1.3333333 | F40: =D40*$B$7/$B$5 -> 0.66666667 | G40: =(B40-E40)^2/E40 -> 0.083333333 | H40: =(C40-F40)^2/F40 -> 0.16666667 | I40: =SUM(G40:H40) -> 0.25
A41: χ² kopā | I41: =SUM(I39:I40) -> 0.75

Sheet Iterācijas
A1: Mezgls | B1: Nosacījums | C1: N | D1: Klase 0 | E1: Klase 1 | F1: Izvēlētā pazīme | G1: χ² | H1: Kategorijas | I1: Izvēles pamatojums
A2: M1 | B2: Visi 15 ieraksti | C2: ='Mezgls_1'!B5 -> 15 | D2: ='Mezgls_1'!B6 -> 8 | E2: ='Mezgls_1'!B7 -> 7 | F2: Dzimums | G2: ='Mezgls_1'!I40 -> 8.0404974 | H2: 2 | I2: Dzimumam ir lielākais χ² = 8,040497. Sievietēm klase 1 ir 6/7, vīriešiem — 1/8.
A3: M2 | B3: Dzimums = s | C3: ='Mezgls_2'!B5 -> 7 | D3: ='Mezgls_2'!B6 -> 1 | E3: ='Mezgls_2'!B7 -> 6 | F3: Vecums | G3: ='Mezgls_2'!I34 -> 7 | H3: 5 | I3: Vecumam χ² = 7 ir vienīgais maksimums. Dzīvojamajai platībai, bērnu skaitam un ienākumiem χ² = 14/9.
A4: M3 | B4: Dzimums = v | C4: ='Mezgls_3'!B5 -> 8 | D4: ='Mezgls_3'!B6 -> 7 | E4: ='Mezgls_3'!B7 -> 1 | F4: Dzīvojamā platība | G4: ='Mezgls_3'!I40 -> 1.9047619 | H4: 2 | I4: Četrām pazīmēm χ² = 40/21. Dzīvojamajai platībai ir 2 vērtības, pārējām — 3; izvēlamies divus zarus.
A5: M4 | B5: Dzimums = v UN Dzīvojamā platība = īpašnieks | C5: ='Mezgls_4'!B5 -> 3 | D5: ='Mezgls_4'!B6 -> 2 | E5: ='Mezgls_4'!B7 -> 1 | F5: Vecums | G5: ='Mezgls_4'!I26 -> 3 | H5: 2 | I5: Vecumam un bērnu skaitam χ² = 3. Vecumam ir 2 vērtības, bērnu skaitam — 3; ienākumiem χ² = 0,75.

Sheet Koks
A1: Koks | B1: 4 mezgli; 8 likumi
A2: Dzimums | B2: v = vīrietis; s = sieviete
A3: Klase | B3: 0 = nepirks; 1 = nopirks

Sheet Likumi
A1: Likums | B1: JA | C1: TAD: klase | D1: Rezultāts | E1: N | F1: Ierakstu ID
A2: R1 | B2: Dzimums = s UN Vecums = 25 | C2: 0 | D2: nepirks iPhone | E2: 1 | F2: 11
A3: R2 | B3: Dzimums = s UN Vecums = 29 | C3: 1 | D3: nopirks iPhone | E3: 1 | F3: 4
A4: R3 | B4: Dzimums = s UN Vecums = 35 | C4: 1 | D4: nopirks iPhone | E4: 1 | F4: 15
A5: R4 | B5: Dzimums = s UN Vecums = 40 | C5: 1 | D5: nopirks iPhone | E5: 2 | F5: 7, 14
A6: R5 | B6: Dzimums = s UN Vecums = 48 | C6: 1 | D6: nopirks iPhone | E6: 2 | F6: 3, 10
A7: R6 | B7: Dzimums = v UN Dzīvojamā platība = īpašnieks UN Vecums = 35 | C7: 0 | D7: nepirks iPhone | E7: 2 | F7: 2, 9
A8: R7 | B8: Dzimums = v UN Dzīvojamā platība = īpašnieks UN Vecums = 40 | C8: 1 | D8: nopirks iPhone | E8: 1 | F8: 13
A9: R8 | B9: Dzimums = v UN Dzīvojamā platība = īrē | C9: 0 | D9: nepirks iPhone | E9: 5 | F9: 1, 5, 6, 8, 12

Sheet Pārbaude
A1: ID | B1: Patiesā klase | C1: Koka prognoze | D1: Likums | E1: Pareizi (1/0)
A2: ='Dati'!A2 -> 1 | B2: ='Dati'!G2 -> 0 | C2: =IF('Dati'!B2="s",IF('Dati'!C2=25,0,IF('Dati'!C2=29,1,IF('Dati'!C2=35,1,IF('Dati'!C2=40,1,IF('Dati'!C2=48,1,"Ārpus koka"))))),IF('Dati'!B2="v",IF('Dati'!D2="īpašnieks",IF('Dati'!C2=35,0,IF('Dati'!C2=40,1,"Ārpus koka")),IF('Dati'!D2="īrē",0,"Ārpus koka")),"Ārpus koka")) -> 0 | D2: =IF('Dati'!B2="s",IF('Dati'!C2=25,"R1",IF('Dati'!C2=29,"R2",IF('Dati'!C2=35,"R3",IF('Dati'!C2=40,"R4",IF('Dati'!C2=48,"R5","Ārpus koka"))))),IF('Dati'!B2="v",IF('Dati'!D2="īpašnieks",IF('Dati'!C2=35,"R6",IF('Dati'!C2=40,"R7","Ārpus koka")),IF('Dati'!D2="īrē","R8","Ārpus koka")),"Ārpus koka")) -> R8 | E2: =IF(B2=C2,1,0) -> 1
A3: ='Dati'!A3 -> 2 | B3: ='Dati'!G3 -> 0 | C3: =IF('Dati'!B3="s",IF('Dati'!C3=25,0,IF('Dati'!C3=29,1,IF('Dati'!C3=35,1,IF('Dati'!C3=40,1,IF('Dati'!C3=48,1,"Ārpus koka"))))),IF('Dati'!B3="v",IF('Dati'!D3="īpašnieks",IF('Dati'!C3=35,0,IF('Dati'!C3=40,1,"Ārpus koka")),IF('Dati'!D3="īrē",0,"Ārpus koka")),"Ārpus koka")) -> 0 | D3: =IF('Dati'!B3="s",IF('Dati'!C3=25,"R1",IF('Dati'!C3=29,"R2",IF('Dati'!C3=35,"R3",IF('Dati'!C3=40,"R4",IF('Dati'!C3=48,"R5","Ārpus koka"))))),IF('Dati'!B3="v",IF('Dati'!D3="īpašnieks",IF('Dati'!C3=35,"R6",IF('Dati'!C3=40,"R7","Ārpus koka")),IF('Dati'!D3="īrē","R8","Ārpus koka")),"Ārpus koka")) -> R6 | E3: =IF(B3=C3,1,0) -> 1
A4: ='Dati'!A4 -> 3 | B4: ='Dati'!G4 -> 1 | C4: =IF('Dati'!B4="s",IF('Dati'!C4=25,0,IF('Dati'!C4=29,1,IF('Dati'!C4=35,1,IF('Dati'!C4=40,1,IF('Dati'!C4=48,1,"Ārpus koka"))))),IF('Dati'!B4="v",IF('Dati'!D4="īpašnieks",IF('Dati'!C4=35,0,IF('Dati'!C4=40,1,"Ārpus koka")),IF('Dati'!D4="īrē",0,"Ārpus koka")),"Ārpus koka")) -> 1 | D4: =IF('Dati'!B4="s",IF('Dati'!C4=25,"R1",IF('Dati'!C4=29,"R2",IF('Dati'!C4=35,"R3",IF('Dati'!C4=40,"R4",IF('Dati'!C4=48,"R5","Ārpus koka"))))),IF('Dati'!B4="v",IF('Dati'!D4="īpašnieks",IF('Dati'!C4=35,"R6",IF('Dati'!C4=40,"R7","Ārpus koka")),IF('Dati'!D4="īrē","R8","Ārpus koka")),"Ārpus koka")) -> R5 | E4: =IF(B4=C4,1,0) -> 1
A5: ='Dati'!A5 -> 4 | B5: ='Dati'!G5 -> 1 | C5: =IF('Dati'!B5="s",IF('Dati'!C5=25,0,IF('Dati'!C5=29,1,IF('Dati'!C5=35,1,IF('Dati'!C5=40,1,IF('Dati'!C5=48,1,"Ārpus koka"))))),IF('Dati'!B5="v",IF('Dati'!D5="īpašnieks",IF('Dati'!C5=35,0,IF('Dati'!C5=40,1,"Ārpus koka")),IF('Dati'!D5="īrē",0,"Ārpus koka")),"Ārpus koka")) -> 1 | D5: =IF('Dati'!B5="s",IF('Dati'!C5=25,"R1",IF('Dati'!C5=29,"R2",IF('Dati'!C5=35,"R3",IF('Dati'!C5=40,"R4",IF('Dati'!C5=48,"R5","Ārpus koka"))))),IF('Dati'!B5="v",IF('Dati'!D5="īpašnieks",IF('Dati'!C5=35,"R6",IF('Dati'!C5=40,"R7","Ārpus koka")),IF('Dati'!D5="īrē","R8","Ārpus koka")),"Ārpus koka")) -> R2 | E5: =IF(B5=C5,1,0) -> 1
A6: ='Dati'!A6 -> 5 | B6: ='Dati'!G6 -> 0 | C6: =IF('Dati'!B6="s",IF('Dati'!C6=25,0,IF('Dati'!C6=29,1,IF('Dati'!C6=35,1,IF('Dati'!C6=40,1,IF('Dati'!C6=48,1,"Ārpus koka"))))),IF('Dati'!B6="v",IF('Dati'!D6="īpašnieks",IF('Dati'!C6=35,0,IF('Dati'!C6=40,1,"Ārpus koka")),IF('Dati'!D6="īrē",0,"Ārpus koka")),"Ārpus koka")) -> 0 | D6: =IF('Dati'!B6="s",IF('Dati'!C6=25,"R1",IF('Dati'!C6=29,"R2",IF('Dati'!C6=35,"R3",IF('Dati'!C6=40,"R4",IF('Dati'!C6=48,"R5","Ārpus koka"))))),IF('Dati'!B6="v",IF('Dati'!D6="īpašnieks",IF('Dati'!C6=35,"R6",IF('Dati'!C6=40,"R7","Ārpus koka")),IF('Dati'!D6="īrē","R8","Ārpus koka")),"Ārpus koka")) -> R8 | E6: =IF(B6=C6,1,0) -> 1
A7: ='Dati'!A7 -> 6 | B7: ='Dati'!G7 -> 0 | C7: =IF('Dati'!B7="s",IF('Dati'!C7=25,0,IF('Dati'!C7=29,1,IF('Dati'!C7=35,1,IF('Dati'!C7=40,1,IF('Dati'!C7=48,1,"Ārpus koka"))))),IF('Dati'!B7="v",IF('Dati'!D7="īpašnieks",IF('Dati'!C7=35,0,IF('Dati'!C7=40,1,"Ārpus koka")),IF('Dati'!D7="īrē",0,"Ārpus koka")),"Ārpus koka")) -> 0 | D7: =IF('Dati'!B7="s",IF('Dati'!C7=25,"R1",IF('Dati'!C7=29,"R2",IF('Dati'!C7=35,"R3",IF('Dati'!C7=40,"R4",IF('Dati'!C7=48,"R5","Ārpus koka"))))),IF('Dati'!B7="v",IF('Dati'!D7="īpašnieks",IF('Dati'!C7=35,"R6",IF('Dati'!C7=40,"R7","Ārpus koka")),IF('Dati'!D7="īrē","R8","Ārpus koka")),"Ārpus koka")) -> R8 | E7: =IF(B7=C7,1,0) -> 1
A8: ='Dati'!A8 -> 7 | B8: ='Dati'!G8 -> 1 | C8: =IF('Dati'!B8="s",IF('Dati'!C8=25,0,IF('Dati'!C8=29,1,IF('Dati'!C8=35,1,IF('Dati'!C8=40,1,IF('Dati'!C8=48,1,"Ārpus koka"))))),IF('Dati'!B8="v",IF('Dati'!D8="īpašnieks",IF('Dati'!C8=35,0,IF('Dati'!C8=40,1,"Ārpus koka")),IF('Dati'!D8="īrē",0,"Ārpus koka")),"Ārpus koka")) -> 1 | D8: =IF('Dati'!B8="s",IF('Dati'!C8=25,"R1",IF('Dati'!C8=29,"R2",IF('Dati'!C8=35,"R3",IF('Dati'!C8=40,"R4",IF('Dati'!C8=48,"R5","Ārpus koka"))))),IF('Dati'!B8="v",IF('Dati'!D8="īpašnieks",IF('Dati'!C8=35,"R6",IF('Dati'!C8=40,"R7","Ārpus koka")),IF('Dati'!D8="īrē","R8","Ārpus koka")),"Ārpus koka")) -> R4 | E8: =IF(B8=C8,1,0) -> 1
A9: ='Dati'!A9 -> 8 | B9: ='Dati'!G9 -> 0 | C9: =IF('Dati'!B9="s",IF('Dati'!C9=25,0,IF('Dati'!C9=29,1,IF('Dati'!C9=35,1,IF('Dati'!C9=40,1,IF('Dati'!C9=48,1,"Ārpus koka"))))),IF('Dati'!B9="v",IF('Dati'!D9="īpašnieks",IF('Dati'!C9=35,0,IF('Dati'!C9=40,1,"Ārpus koka")),IF('Dati'!D9="īrē",0,"Ārpus koka")),"Ārpus koka")) -> 0 | D9: =IF('Dati'!B9="s",IF('Dati'!C9=25,"R1",IF('Dati'!C9=29,"R2",IF('Dati'!C9=35,"R3",IF('Dati'!C9=40,"R4",IF('Dati'!C9=48,"R5","Ārpus koka"))))),IF('Dati'!B9="v",IF('Dati'!D9="īpašnieks",IF('Dati'!C9=35,"R6",IF('Dati'!C9=40,"R7","Ārpus koka")),IF('Dati'!D9="īrē","R8","Ārpus koka")),"Ārpus koka")) -> R8 | E9: =IF(B9=C9,1,0) -> 1
A10: ='Dati'!A10 -> 9 | B10: ='Dati'!G10 -> 0 | C10: =IF('Dati'!B10="s",IF('Dati'!C10=25,0,IF('Dati'!C10=29,1,IF('Dati'!C10=35,1,IF('Dati'!C10=40,1,IF('Dati'!C10=48,1,"Ārpus koka"))))),IF('Dati'!B10="v",IF('Dati'!D10="īpašnieks",IF('Dati'!C10=35,0,IF('Dati'!C10=40,1,"Ārpus koka")),IF('Dati'!D10="īrē",0,"Ārpus koka")),"Ārpus koka")) -> 0 | D10: =IF('Dati'!B10="s",IF('Dati'!C10=25,"R1",IF('Dati'!C10=29,"R2",IF('Dati'!C10=35,"R3",IF('Dati'!C10=40,"R4",IF('Dati'!C10=48,"R5","Ārpus koka"))))),IF('Dati'!B10="v",IF('Dati'!D10="īpašnieks",IF('Dati'!C10=35,"R6",IF('Dati'!C10=40,"R7","Ārpus koka")),IF('Dati'!D10="īrē","R8","Ārpus koka")),"Ārpus koka")) -> R6 | E10: =IF(B10=C10,1,0) -> 1
A11: ='Dati'!A11 -> 10 | B11: ='Dati'!G11 -> 1 | C11: =IF('Dati'!B11="s",IF('Dati'!C11=25,0,IF('Dati'!C11=29,1,IF('Dati'!C11=35,1,IF('Dati'!C11=40,1,IF('Dati'!C11=48,1,"Ārpus koka"))))),IF('Dati'!B11="v",IF('Dati'!D11="īpašnieks",IF('Dati'!C11=35,0,IF('Dati'!C11=40,1,"Ārpus koka")),IF('Dati'!D11="īrē",0,"Ārpus koka")),"Ārpus koka")) -> 1 | D11: =IF('Dati'!B11="s",IF('Dati'!C11=25,"R1",IF('Dati'!C11=29,"R2",IF('Dati'!C11=35,"R3",IF('Dati'!C11=40,"R4",IF('Dati'!C11=48,"R5","Ārpus koka"))))),IF('Dati'!B11="v",IF('Dati'!D11="īpašnieks",IF('Dati'!C11=35,"R6",IF('Dati'!C11=40,"R7","Ārpus koka")),IF('Dati'!D11="īrē","R8","Ārpus koka")),"Ārpus koka")) -> R5 | E11: =IF(B11=C11,1,0) -> 1
A12: ='Dati'!A12 -> 11 | B12: ='Dati'!G12 -> 0 | C12: =IF('Dati'!B12="s",IF('Dati'!C12=25,0,IF('Dati'!C12=29,1,IF('Dati'!C12=35,1,IF('Dati'!C12=40,1,IF('Dati'!C12=48,1,"Ārpus koka"))))),IF('Dati'!B12="v",IF('Dati'!D12="īpašnieks",IF('Dati'!C12=35,0,IF('Dati'!C12=40,1,"Ārpus koka")),IF('Dati'!D12="īrē",0,"Ārpus koka")),"Ārpus koka")) -> 0 | D12: =IF('Dati'!B12="s",IF('Dati'!C12=25,"R1",IF('Dati'!C12=29,"R2",IF('Dati'!C12=35,"R3",IF('Dati'!C12=40,"R4",IF('Dati'!C12=48,"R5","Ārpus koka"))))),IF('Dati'!B12="v",IF('Dati'!D12="īpašnieks",IF('Dati'!C12=35,"R6",IF('Dati'!C12=40,"R7","Ārpus koka")),IF('Dati'!D12="īrē","R8","Ārpus koka")),"Ārpus koka")) -> R1 | E12: =IF(B12=C12,1,0) -> 1
A13: ='Dati'!A13 -> 12 | B13: ='Dati'!G13 -> 0 | C13: =IF('Dati'!B13="s",IF('Dati'!C13=25,0,IF('Dati'!C13=29,1,IF('Dati'!C13=35,1,IF('Dati'!C13=40,1,IF('Dati'!C13=48,1,"Ārpus koka"))))),IF('Dati'!B13="v",IF('Dati'!D13="īpašnieks",IF('Dati'!C13=35,0,IF('Dati'!C13=40,1,"Ārpus koka")),IF('Dati'!D13="īrē",0,"Ārpus koka")),"Ārpus koka")) -> 0 | D13: =IF('Dati'!B13="s",IF('Dati'!C13=25,"R1",IF('Dati'!C13=29,"R2",IF('Dati'!C13=35,"R3",IF('Dati'!C13=40,"R4",IF('Dati'!C13=48,"R5","Ārpus koka"))))),IF('Dati'!B13="v",IF('Dati'!D13="īpašnieks",IF('Dati'!C13=35,"R6",IF('Dati'!C13=40,"R7","Ārpus koka")),IF('Dati'!D13="īrē","R8","Ārpus koka")),"Ārpus koka")) -> R8 | E13: =IF(B13=C13,1,0) -> 1
... A16: ='Dati'!A16 -> 15 | B16: ='Dati'!G16 -> 1 | C16: =IF('Dati'!B16="s",IF('Dati'!C16=25,0,IF('Dati'!C16=29,1,IF('Dati'!C16=35,1,IF('Dati'!C16=40,1,IF('Dati'!C16=48,1,"Ārpus koka"))))),IF('Dati'!B16="v",IF('Dati'!D16="īpašnieks",IF('Dati'!C16=35,0,IF('Dati'!C16=40,1,"Ārpus koka")),IF('Dati'!D16="īrē",0,"Ārpus koka")),"Ārpus koka")) -> 1 | D16: =IF('Dati'!B16="s",IF('Dati'!C16=25,"R1",IF('Dati'!C16=29,"R2",IF('Dati'!C16=35,"R3",IF('Dati'!C16=40,"R4",IF('Dati'!C16=48,"R5","Ārpus koka"))))),IF('Dati'!B16="v",IF('Dati'!D16="īpašnieks",IF('Dati'!C16=35,"R6",IF('Dati'!C16=40,"R7","Ārpus koka")),IF('Dati'!D16="īrē","R8","Ārpus koka")),"Ārpus koka")) -> R3 | E16: =IF(B16=C16,1,0) -> 1
A19: Pareizi | B19: =SUM(E2:E16) -> 15
A20: Kopā | B20: =COUNTA(A2:A16) -> 15
A21: Precizitāte | B21: =B19/B20 -> 1
A23: Piezīme | B23: Tie paši 15 mācību ieraksti; tā nav jaunu klientu pārbaude.

Sheet Secinājumi
A1: Lauks | B1: Apraksts
A2: Kāpēc saknē dzimums? | B2: Sieviešu grupā nopirks 6 no 7 klientiem, vīriešu grupā — 1 no 8. χ² = 8,040497 ir lielāks nekā vecumam (4,486607), dzīvojamajai platībai (0,044643), bērniem (2,678571) un ienākumiem (5,290179).
A3: Sieviešu zars | B3: 25 gadus vecajai sievietei (ID 11) klase ir 0. Vecumiem 29, 35, 40 un 48 šajā grupā ir tikai klase 1. Sašķelšana pēc vecuma uzreiz dod piecas tīras lapas.
A4: Vīriešu zars | B4: Pieciem vīriešiem, kas īrē mājokli, klase ir 0 (ID 1, 5, 6, 8, 12). Starp īpašniekiem divi 35 gadus vecie klienti nepērk (ID 2, 9), bet 40 gadus vecais pērk (ID 13). Īpašums pats par sevi negarantē pirkumu.
A5: Vienādas χ² vērtības | B5: Vīriešu grupā četrām atlikušajām pazīmēm χ² = 40/21. Palīgnoteikums izvēlas dzīvojamo platību ar 2 kategorijām. Tāpēc šajā kokā ir 8 likumi; ja vienmēr izvēlētos pirmo kolonnu, rezultāts būtu 9 likumi.
A6: Pārbaudes rezultāts | B6: 4 iekšējie mezgli un 8 gala lapas. Excel pārbaudes formulas dod 15/15 pareizas prognozes jeb 100% uz šīs pašas tabulas. Tīrās lapas izskaidro šo rezultātu.
A7: Ko nevar secināt? | B7: Ir tikai 15 ieraksti, vairākās lapās — viens klients. Rezultāts nepierāda, ka dzimums vai īpašums izraisa pirkumu. Jaunu klientu precizitāte nav pārbaudīta; nezināmai kategorijai prognozes formula rāda “Ārpus koka”.
